<?xml version='1.0'?>

<robot name="wheel" xmlns:xacro="http://www.ros.org/wiki/xacro">
  <link name='base_link'>
    <pose>0 0 0 0 0 0</pose>

    <inertial>
      <mass value="15.0"/>
      <origin xyz="-0.215 0 0.39" rpy=" 0 0 0"/>
      <inertia
          ixx="0.473625" ixy="0" ixz="0"
          iyy="0.47928125" iyz="0"
          izz="0.51190625"
      />
    </inertial>

    <collision name='collision'>
      <origin xyz="-0.215 0 0.39" rpy=" 0 0 0"/>
      <geometry>
        <box size="0.455 0.45 0.42"/>
      </geometry>
    </collision>

    <visual name='base_link_visual'>
      <origin xyz="-0.215 0 0.39" rpy=" 0 0 0"/>
      <geometry>
        <box size="0.455 0.45 0.42"/>
      </geometry>
    </visual>

</link>

 <link name="caster_link">
    <collision >
      <origin xyz="0 0 0.09" rpy=" 0 0 0"/>
      <geometry>
        <sphere radius="0.09"/>
      </geometry>
      <surface>
        <friction>
          <ode>
            <mu>0</mu>
            <mu2>0</mu2>
            <slip1>1.0</slip1>
            <slip2>1.0</slip2>
          </ode>
        </friction>
      </surface>
    </collision>

    <visual >
      <origin xyz="0 0 0.09" rpy=" 0 0 0"/>
      <geometry>
        <sphere radius="0.09"/>
      </geometry>
    </visual>

 <inertial>
      <origin xyz="0 0 0"/>
      <mass value="0.500"/>
      <inertia ixx="0.00025" ixy="0" ixz="0" iyy="0.00025"  iyz="0" izz="0.00025"/>
    </inertial>
 
  </link>
    <joint name="caster_joint" type="fixed">
    <parent link="base_link"/>
    <child link="caster_link"/>
    <origin xyz="0 0 0"/>
  </joint>

<link name="base_footprint"/>
  <joint name="base_link_joint" type="fixed">
    <parent link="base_footprint"/>
    <child link="base_link"/>
    <origin xyz="0 0 0.100"/>
  </joint>

  <link name="left_wheel">
    <!--origin xyz="0.1 0.13 0.1" rpy="0 1.5707 1.5707"/-->
    <collision name="collision">
      <origin xyz="0 0 0" rpy="0 0 0"/>
      <geometry>
        <cylinder radius="0.2794" length="0.05"/>
      </geometry>
    </collision>
    <visual name="left_wheel_visual">
      <origin xyz="0 0 0" rpy="0 0 0"/>
      <geometry>
        <cylinder radius="0.2794" length="0.05"/>
      </geometry>
    </visual>
    <inertial>
      <origin xyz="0 0 0" rpy="0 0 0"/>
      <mass value="5"/>
      <inertia
        ixx=".09904" ixy="0.0" ixz="0.0"
        iyy=".09904" iyz="0.0"
        izz=".196"/>
    </inertial>
  </link>

  <link name="right_wheel">
    <!--origin xyz="0.1 -0.13 0.1" rpy="0 1.5707 1.5707"/-->
    <collision name="collision">
      <origin xyz="0 0 0" rpy="0 0 0"/>
      <geometry>
        <cylinder radius="0.2794" length="0.05"/>
      </geometry>
    </collision>
    <visual name="right_wheel_visual">
      <origin xyz="0 0 0" rpy="0 0 0"/>
      <geometry>
        <cylinder radius="0.2794" length="0.05"/>
      </geometry>
    </visual>
    <inertial>
      <origin xyz="0 0 0" rpy="0 0 0"/>
      <mass value="5"/>
      <inertia
        ixx=".09904" ixy="0.0" ixz="0.0"
        iyy=".09904" iyz="0.0"
        izz=".196"/>
    </inertial>
  </link>


  <joint type="continuous" name="left_wheel_hinge">
    <origin xyz="-0.43 0.26 0.28" rpy="-1.5707 0 0"/>
    <!--origin xyz="0.1 0.13 0" rpy="0 1.5707 1.5707"/-->
    <child link="left_wheel"/>
    <parent link="base_link"/>
    <axis xyz="0 0 1"/>
    <limit effort="10000" velocity="1000"/>
    <joint_properties damping="1.0" friction="1.0"/>
  </joint>

  <joint type="continuous" name="right_wheel_hinge">
    <origin xyz="-0.43 -0.26 0.28" rpy="1.5707 0 0"/>
    <!--origin xyz="0.1 -0.13 0" rpy="0 1.5707 1.5707"/-->
    <child link="right_wheel"/>
    <parent link="base_link"/>
    <axis xyz="0 0 1" rpy="0 0 0"/>
    <limit effort="10000" velocity="1000"/>
    <joint_properties damping="1.0" friction="1.0"/>
  </joint>




<!-- Hokuyo Laser -->
  <link name="hokuyo_link">
  </link>

  <joint name="hokuyo_joint" type="fixed">
    <axis xyz="0 0 0" />
    <origin xyz="0.1007 0 0.0558" rpy="0 0 0"/>
    <parent link="base_link"/>
    <child link="hokuyo_link"/>
  </joint>








 <link name="base_imu_link">
  
  
  </link>

 <joint name="imu_joint" type="fixed">
    <axis xyz="0 0 0" />
    <origin xyz="0.1007 0 0.0558" rpy="0 0 0"/>
    <parent link="base_link"/>
    <child link="base_imu_link"/>
  </joint>









  <gazebo>
    <plugin name="differential_drive_controller" filename="libgazebo_ros_diff_drive.so">
      <legacyMode>false</legacyMode>
      <alwaysOn>true</alwaysOn>
      <updateRate>20</updateRate>
      <leftJoint>left_wheel_hinge</leftJoint>
      <rightJoint>right_wheel_hinge</rightJoint>
      <wheelSeparation>0.4</wheelSeparation>
      <wheelDiameter>0.1</wheelDiameter>
      <torque>20</torque>
      <commandTopic>cmd_vel</commandTopic>
      <odometryTopic>odom</odometryTopic>
      <odometryFrame>odom</odometryFrame>
      <robotBaseFrame>chassis</robotBaseFrame>
    </plugin>
  </gazebo>

  <gazebo reference="chassis">
      <material>Gazebo/Orange</material>
    </gazebo>


</robot>

